Workbook

Sheet Puzzles
A1: Day | B1: Publish date | C1: Origin | D1: ID | E1: Category | F1: Theme | G1: Low label | H1: High label | I1: Item 1 | J1: Item 2 | K1: Item 3 | L1: Item 4 | M1: Item 5 | N1: Item 6 | O1: Source | P1: Source URL | Q1: Verified by | R1: Verified date | S1: Status | T1: Notes | U1: Reviewed? | V1: Comments
A2: 1 | B2: 2026-08-20 | C2: New | D2: 2026-08-20-us-states-population | E2: geography | F2: US states by population | G2: Fewest people | H2: Most people | I2: Illinois | J2: Pennsylvania | K2: New York | L2: Florida | M2: Texas | N2: California | O2: US Census Bureau, 2020 Census | P2: https://www.census.gov/ | Q2: VS | R2: 46245 | S2: approved | T2: 2020 populations: about 12.8, 13.0, 20.2, 21.5, 29.1 and 39.5 million. | U2: No
A3: 2 | B3: 2026-08-21 | C3: New | D3: 2026-08-27-star-colours-temperature | E3: astronomy | F3: Star colours by temperature | G3: Coolest | H3: Hottest | I3: Red | J3: Orange | K3: Yellow | L3: White | M3: Blue-white | N3: Blue | O3: Stellar classification (spectral types) | P3: https://science.nasa.gov/ | Q3: VS | R3: 46254 | S3: approved | T3: Cooler stars glow red; the hottest glow blue, from roughly 3,000 K to over 25,000 K. | U3: No
A4: 3 | B4: 2026-08-22 | C4: New | D4: 2026-08-28-drinks-alcohol-content | E4: culture | F4: Drinks by alcohol content | G4: Lowest | H4: Highest | I4: Beer | J4: Wine | K4: Fortified wine | L4: Liqueur | M4: Spirits | N4: Overproof rum | O4: Typical alcohol-by-volume ranges | P4: https://www.britannica.com/ | Q4: VS | R4: 46254 | S4: approved | T4: Roughly 5, 12, 18, 25, 40 and 75 percent alcohol by volume. | U4: No
A5: 4 | B5: 2026-08-23 | C5: New | D5: 2026-08-29-lakes-surface-area | E5: geography | F5: Lakes by surface area | G5: Smallest | H5: Largest | I5: Great Bear Lake | J5: Lake Michigan | K5: Lake Huron | L5: Lake Victoria | M5: Lake Superior | N5: Caspian Sea | O5: Encyclopaedia Britannica, world's largest lakes | P5: https://www.britannica.com/topic/worlds-largest-lakes-2228655 | Q5: VS | R5: 46254 | S5: approved | T5: In square km: Great Bear Lake (31,328); Lake Michigan (57,757); Lake Huron (59,570); Lake Victoria (69,484); Lake Superior (82,100); and the Caspian Sea (149,200), the world’s largest salt lake. | U5: No
A6: 5 | B6: 2026-08-24 | C6: New | D6: 2026-08-30-explorers-voyage | E6: history | F6: Explorers by voyage | G6: Earliest | H6: Most recent | I6: Marco Polo | J6: Christopher Columbus | K6: Vasco da Gama | L6: Ferdinand Magellan | M6: James Cook | N6: Roald Amundsen | O6: Encyclopaedia Britannica, individual biographies | P6: https://www.britannica.com/topic/European-exploration/The-Age-of-Discovery | Q6: VS | R6: 46254 | S6: approved | T6: By the era of their best-known journeys: c.1271, 1492, 1498, 1519, 1768 and 1911. | U6: No
A7: 6 | B7: 2026-08-25 | C7: New | D7: 2026-08-31-nato-officer-ranks | E7: military | F7: Military officer ranks by NATO seniority code | G7: Most junior | H7: Most senior | I7: Second Lieutenant | J7: Captain | K7: Major | L7: Lieutenant Colonel | M7: Colonel | N7: Brigadier General | O7: NATO STANAG 2116 | P7: https://en.wikipedia.org/wiki/NATO_military_rank_codes | Q7: VS | R7: 46254 | S7: approved | T7: Officer Ranks (OF): OF-1, OF-2, OF-3, OF-4, OF-5, and OF-6 respectively (UK/US Army). | U7: No
A8: 7 | B8: 2026-08-26 | C8: New | D8: 2026-09-01-radio-frequency-bands | E8: technology | F8: Radio frequency bands | G8: Lowest frequency | H8: Highest frequency | I8: ELF | J8: LF | K8: MF | L8: HF | M8: UHF | N8: SHF | O8: ITU Radio Regulations, Article 2 (frequency/wavelength band definitions) | P8: https://en.wikipedia.org/wiki/Radio_spectrum | Q8: VS | R8: 46254 | S8: approved | T8: Standard ITU classification | U8: No
A9: 8 | B9: 2026-08-27 | C9: New | D9: 2026-09-02-units-length-size | E9: measurement | F9: Units of length by size | G9: Shortest | H9: Longest | I9: Millimetre | J9: Centimetre | K9: Inch | L9: Foot | M9: Yard | N9: Metre | O9: SI and imperial definitions | P9: https://www.nist.gov/ | Q9: VS | R9: 46254 | S9: approved | T9: 1, 10, 25.4, 304.8, 914.4 and 1000 millimetres; a yard is just short of a metre. | U9: No
A10: 9 | B10: 2026-08-28 | C10: New | D10: 2026-09-03-musical-tempo-markings | E10: music | F10: Musical tempo markings by speed | G10: Slowest | H10: Fastest | I10: Largo | J10: Adagio | K10: Andante | L10: Moderato | M10: Allegro | N10: Presto | O10: Standard tempo terms (beats per minute ranges) | P10: https://www.britannica.com/art/tempo-music | Q10: VS | R10: 46254 | S10: approved | T10: From a broad, slow largo to a very fast presto. | U10: No
A11: 10 | B11: 2026-08-29 | C11: New | D11: 2026-09-04-animals-resting-heart | E11: nature | F11: Animals by resting heart rate | G11: Slowest | H11: Fastest | I11: Elephant | J11: Human | K11: Dog | L11: Cat | M11: Mouse | N11: Hummingbird | O11: Comparative physiology references (typical resting rates) | P11: https://www.britannica.com/ | Q11: VS | R11: 46254 | S11: approved | T11: From about 30 beats per minute in an elephant to over 1,000 in a hummingbird. | U11: No
A12: 11 | B12: 2026-08-30 | C12: New | D12: 2026-09-05-chilli-peppers-heat | E12: science | F12: Chilli peppers by heat | G12: Mildest | H12: Hottest | I12: Bell pepper | J12: Jalapeno | K12: Serrano | L12: Cayenne | M12: Habanero | N12: Carolina Reaper | O12: Scoville heat scale (typical ranges) | P12: https://www.britannica.com/topic/Scoville-scale | Q12: VS | R12: 46254 | S12: approved | T12: From 0 Scoville heat units for a bell pepper to over a million for the Carolina Reaper. | U12: No
A13: 12 | B13: 2026-08-31 | C13: New | D13: 2026-09-06-screen-resolutions-sharpness | E13: technology | F13: Screen resolutions by sharpness | G13: Fewest pixels | H13: Most pixels | I13: SD | J13: HD | K13: Full HD | L13: QHD | M13: 4K | N13: 8K | O13: Standard display resolutions (total pixel count) | P13: https://www.britannica.com/ | Q13: VS | R13: 46254 | S13: approved | T13: Pixels (p): 480p; 720p; 1080p; 1440p; 2160p; and 4320p, respectively. | U13: No
A14: 13 | B14: 2026-09-01 | C14: Existing | D14: 2026-06-01-planets-distance | E14: astronomy | F14: Planets by distance from the Sun | G14: Closest to the Sun | H14: Farthest from the Sun | I14: Mercury | J14: Venus | K14: Earth | L14: Mars | M14: Jupiter | N14: Saturn | O14: NASA Solar System Exploration | P14: https://science.nasa.gov/solar-system/ | Q14: VS | R14: 46162 | S14: approved | T14: Order of the planets outward from the Sun is fixed.
A15: 14 | B15: 2026-09-02 | C15: Existing | D15: 2026-06-02-history-events | E15: history | F15: Moments in history | G15: Earliest | H15: Most recent | I15: Great Pyramid of Giza built | J15: Fall of the Western Roman Empire | K15: Gutenberg's printing press | L15: US Declaration of Independence | M15: First powered flight | N15: First Moon landing | O15: Encyclopaedia Britannica, individual event entries | P15: https://www.britannica.com/ | Q15: VS | R15: 46162 | S15: approved | T15: Dates are centuries apart, so the chronology is unambiguous.
A16: 15 | B16: 2026-09-03 | C16: Existing | D16: 2026-06-03-planets-size | E16: astronomy | F16: Planets by size | G16: Smallest diameter | H16: Largest diameter | I16: Mercury | J16: Mars | K16: Venus | L16: Earth | M16: Neptune | N16: Jupiter | O16: NASA planetary fact sheets (mean diameter) | P16: https://nssdc.gsfc.nasa.gov/planetary/factsheet/ | Q16: VS | R16: 46162 | S16: approved | T16: Earth is slightly larger than Venus by mean diameter.
A17: 16 | B17: 2026-09-04 | C17: Existing | D17: 2026-06-04-mohs | E17: geology | F17: Minerals on the Mohs hardness scale | G17: Softest | H17: Hardest | I17: Talc | J17: Gypsum | K17: Calcite | L17: Apatite | M17: Quartz | N17: Diamond | O17: Mohs scale of mineral hardness, standard mineralogy reference | P17: https://www.usgs.gov/ | Q17: VS | R17: 46162 | S17: approved | T17: Talc is 1, diamond is 10 on the scale.
A18: 17 | B18: 2026-09-05 | C18: Existing | D18: 2026-06-05-peaks | E18: geography | F18: Peaks by height above sea level | G18: Shortest | H18: Tallest | I18: Mount Olympus | J18: Mount Fuji | K18: Mont Blanc | L18: Kilimanjaro | M18: Aconcagua | N18: Mount Everest | O18: Encyclopaedia Britannica, individual mountain entries | P18: https://www.britannica.com/place/Mount-Everest | Q18: VS | R18: 46162 | S18: approved | T18: Heights are well separated, so rounding does not change order.
A19: 18 | B19: 2026-09-06 | C19: Existing | D19: 2026-06-06-countries-area | E19: geography | F19: Countries by land area | G19: Smallest | H19: Largest | I19: United Kingdom | J19: Japan | K19: Egypt | L19: India | M19: China | N19: Russia | O19: The World Factbook, country area figures | P19: https://www.cia.gov/the-world-factbook/ | Q19: VS | R19: 46162 | S19: approved | T19: Areas differ by large margins, so order is stable.
A20: 19 | B20: 2026-09-07 | C20: Existing | D20: 2026-06-07-population | E20: geography | F20: Places by population | G20: Fewest people | H20: Most people | I20: Iceland | J20: New Zealand | K20: Australia | L20: Germany | M20: United States | N20: India | O20: UN World Population Prospects | P20: https://population.un.org/wpp/ | Q20: VS | R20: 46162 | S20: approved | T20: Chosen so each step is a large, stable gap.
A21: 20 | B21: 2026-09-08 | C21: Existing | D21: 2026-06-08-geological-periods | E21: geology | F21: Geological periods | G21: Earliest | H21: Most recent | I21: Cambrian | J21: Devonian | K21: Permian | L21: Triassic | M21: Jurassic | N21: Cretaceous | O21: International Commission on Stratigraphy, geologic time scale | P21: https://stratigraphy.org/chart | Q21: VS | R21: 46190 | S21: approved | T21: Jurassic precedes Cretaceous.
A22: 21 | B22: 2026-09-09 | C22: Existing | D22: 2026-06-09-time-units | E22: measurement | F22: Units of time by length | G22: Shortest | H22: Longest | I22: Second | J22: Minute | K22: Hour | L22: Day | M22: Week | N22: Year | O22: International System of Units (SI), BIPM | P22: https://www.bipm.org/ | Q22: VS | R22: 46190 | S22: approved | T22: Definitional ordering.
A23: 22 | B23: 2026-09-10 | C23: Existing | D23: 2026-06-10-continents-area | E23: geography | F23: Continents by land area | G23: Smallest | H23: Largest | I23: Australia | J23: Europe | K23: Antarctica | L23: South America | M23: North America | N23: Africa | O23: Encyclopaedia Britannica, continent entries | P23: https://www.britannica.com/ | Q23: VS | R23: 46190 | S23: approved | T23: Asia, the largest, is left out so the six fit one screen.
A24: 23 | B24: 2026-09-11 | C24: Existing | D24: 2026-06-11-visible-light | E24: science | F24: Colours of light by wavelength | G24: Shortest wavelength | H24: Longest wavelength | I24: Violet | J24: Blue | K24: Green | L24: Yellow | M24: Orange | N24: Red | O24: Encyclopaedia Britannica, visible spectrum | P24: https://www.britannica.com/science/visible-spectrum | Q24: VS | R24: 46190 | S24: approved | T24: Violet is shortest, red is longest in the visible range.
A25: 24 | B25: 2026-09-12 | C25: Existing | D25: 2026-06-12-us-wars | E25: history | F25: United States conflicts in time | G25: Earliest | H25: Most recent | I25: American Revolution | J25: American Civil War | K25: World War I | L25: World War II | M25: Korean War | N25: Vietnam War | O25: Encyclopaedia Britannica, individual conflict entries | P25: https://www.britannica.com/ | Q25: VS | R25: 46190 | S25: approved | T25: Start dates 1775, 1861, 1914, 1939, 1950 and 1955.
... A41: 40 | B41: 2026-09-28 | C41: Existing | D41: 2026-06-28-taxonomy | E41: nature | F41: Levels of biological classification | G41: Narrowest | H41: Broadest | I41: Species | J41: Genus | K41: Family | L41: Order | M41: Class | N41: Phylum | O41: Encyclopaedia Britannica, taxonomy | P41: https://www.britannica.com/science/taxonomy | Q41: VS | R41: 46190 | S41: approved | T41: Each rank groups the one before it.
A42: 41 | B42: 2026-09-29 | C42: Existing | D42: 2026-06-30-structures-height | E42: geography | F42: Famous structures by height | G42: Shortest | H42: Tallest | I42: Statue of Liberty | J42: Eiffel Tower | K42: Empire State Building | L42: CN Tower | M42: Shanghai Tower | N42: Burj Khalifa | O42: Encyclopaedia Britannica, individual structure entries | P42: https://www.britannica.com/ | Q42: VS | R42: 46190 | S42: approved | T42: Heights are well separated across the six. | U42: Yes
A43: 42 | B43: 2026-09-30 | C43: Existing | D43: 2026-07-01-everyday-temps | E43: science | F43: Everyday temperatures | G43: Coldest | H43: Hottest | I43: Water freezes | J43: Fridge interior | K43: Room temperature | L43: Human body | M43: Water boils | N43: Roasting oven | O43: General physics reference (degrees Celsius) | P43: https://www.britannica.com/ | Q43: VS | R43: 46190 | S43: approved | T43: 0, 4, 20, 37, 100 and about 200 degrees Celsius.
A44: 43 | B44: 2026-10-01 | C44: Existing | D44: 2026-07-02-olympics | E44: history | F44: Summer Olympic host cities in time | G44: Earliest | H44: Most recent | I44: Beijing | J44: London | K44: Rio de Janeiro | L44: Tokyo | M44: Paris | N44: Los Angeles | O44: International Olympic Committee | P44: https://olympics.com/ | Q44: VS | R44: 46190 | S44: approved | T44: 2008, 2012, 2016, 2020, 2024 and the 2028 host.
A45: 44 | B45: 2026-10-02 | C45: Existing | D45: 2026-07-03-diameters | E45: astronomy | F45: Worlds by diameter | G45: Smallest | H45: Largest | I45: Moon | J45: Mercury | K45: Mars | L45: Earth | M45: Jupiter | N45: Sun | O45: NASA planetary fact sheets | P45: https://nssdc.gsfc.nasa.gov/planetary/factsheet/ | Q45: VS | R45: 46190 | S45: approved | T45: From the Moon up to the Sun. | U45: Yes
A46: 45 | B46: 2026-10-03 | C46: Existing | D46: 2026-07-04-running-distances | E46: sport | F46: Running distances | G46: Shortest | H46: Longest | I46: 100 metres | J46: 400 metres | K46: 1 mile | L46: 5 km | M46: Half marathon | N46: Marathon | O46: World Athletics, standard event distances | P46: https://worldathletics.org/ | Q46: VS | R46: 46190 | S46: approved | T46: The marathon is 42.195 km.
A47: 46 | B47: 2026-10-04 | C47: Existing | D47: 2026-07-05-poker-hands | E47: games | F47: Poker hands by rank | G47: Weakest | H47: Strongest | I47: High card | J47: One pair | K47: Two pair | L47: Three of a kind | M47: Straight | N47: Flush | O47: Standard poker hand rankings | P47: https://www.britannica.com/topic/poker-card-game | Q47: VS | R47: 46190 | S47: approved | T47: Six of the lower ranks, weakest to strongest. | U47: Yes
A48: 47 | B48: 2026-10-05 | C48: Existing | D48: 2026-07-06-empires | E48: history | F48: Empires by era | G48: Earliest | H48: Most recent | I48: Ancient Egypt | J48: Ancient Greece | K48: Roman Empire | L48: Mongol Empire | M48: Ottoman Empire | N48: British Empire | O48: Encyclopaedia Britannica, individual civilisation entries | P48: https://www.britannica.com/ | Q48: VS | R48: 46190 | S48: approved | T48: By the period each rose to prominence.
A49: 48 | B49: 2026-10-06 | C49: Existing | D49: 2026-07-07-transport-speed | E49: transport | F49: Ways to travel by typical speed | G49: Slowest | H49: Fastest | I49: Walking | J49: Cycling | K49: City driving | L49: Motorway driving | M49: High-speed train | N49: Airliner | O49: General reference (typical speeds) | P49: https://www.britannica.com/ | Q49: VS | R49: 46190 | S49: approved | T49: From a walking pace up to cruising flight.
A50: 49 | B50: 2026-10-07 | C50: Existing | D50: 2026-07-08-math-constants | E50: mathematics | F50: Mathematical constants by value | G50: Smallest | H50: Largest | I50: Zero | J50: One | K50: Square root of 2 | L50: e | M50: Pi | N50: Tau | O50: Encyclopaedia Britannica, mathematical constants | P50: https://www.britannica.com/ | Q50: VS | R50: 46190 | S50: approved | T50: 0, 1, 1.41, 2.72, 3.14 and 6.28.
A51: 50 | B51: 2026-10-08 | C51: Existing | D51: 2026-07-09-the-electromagnetic-spectrum | E51: science | F51: The electromagnetic spectrum | G51: Shortest wavelength | H51: Longest wavelength | I51: Gamma rays | J51: X-rays | K51: Ultraviolet | L51: Visible light | M51: Infrared | N51: Radio waves | O51: NASA, Tour of the Electromagnetic Spectrum | P51: https://science.nasa.gov/ems/ | Q51: VS | R51: 46190 | S51: approved | T51: Gamma rays have the shortest wavelength; radio waves the longest.
A52: 51 | B52: 2026-10-09 | C52: Existing | D52: 2026-07-10-islands-by-land-area | E52: geography | F52: Islands by land area | G52: Smallest | H52: Largest | I52: Sumatra | J52: Baffin Island | K52: Madagascar | L52: Borneo | M52: New Guinea | N52: Greenland | O52: Encyclopaedia Britannica, individual island entries | P52: https://www.britannica.com/ | Q52: VS | R52: 46190 | S52: approved | T52: Greenland is by far the largest of the six; Australia is treated as a continent, not an island.
A53: 52 | B53: 2026-10-10 | C53: Existing | D53: 2026-07-11-the-beaufort-wind-scale | E53: science | F53: The Beaufort wind scale | G53: Calmest | H53: Strongest | I53: Calm | J53: Light breeze | K53: Moderate breeze | L53: Strong breeze | M53: Gale | N53: Storm | O53: UK Met Office, Beaufort wind force scale | P53: https://www.metoffice.gov.uk/ | Q53: VS | R53: 46190 | S53: approved | T53: Beaufort numbers roughly 0, 2, 4, 6, 8 and 10. | U53: Yes
A54: 53 | B54: 2026-10-11 | C54: Existing | D54: 2026-07-12-art-movements-in-time | E54: art | F54: Art movements in time | G54: Earliest | H54: Most recent | I54: Renaissance | J54: Baroque | K54: Impressionism | L54: Cubism | M54: Surrealism | N54: Pop Art | O54: Encyclopaedia Britannica, art movement entries | P54: https://www.britannica.com/ | Q54: VS | R54: 46190 | S54: approved | T54: By the period each flourished: 15th c, 17th c, 1870s, 1900s, 1920s and 1950s. | U54: Yes
A55: 54 | B55: 2026-10-12 | C55: Existing | D55: 2026-07-13-scientists-by-birth | E55: science | F55: Scientists by birth | G55: Earliest born | H55: Latest born | I55: Nicolaus Copernicus | J55: Galileo Galilei | K55: Isaac Newton | L55: Charles Darwin | M55: Albert Einstein | N55: Stephen Hawking | O55: Encyclopaedia Britannica, individual biographies | P55: https://www.britannica.com/ | Q55: VS | R55: 46190 | S55: approved | T55: Born 1473, 1564, 1643, 1809, 1879 and 1942.
...

Sheet Summary
A1: Gradus puzzle review summary
A3: Total puzzles | B3: =COUNTA(Puzzles!D2:D97) -> 96
A4: Existing (approved) | B4: =COUNTIF(Puzzles!S2:S97,"approved") -> 96
A5: Pending review | B5: =COUNTIF(Puzzles!U2:U97,"No") -> 33
A6: Date range | B6: =Puzzles!B2&" to "&Puzzles!B97 -> 2026-08-20 to 2026-11-23
A8: By category | B8: Count
A9: art | B9: =COUNTIF(Puzzles!E2:E97,"art") -> 2
A10: astronomy | B10: =COUNTIF(Puzzles!E2:E97,"astronomy") -> 6
A11: culture | B11: =COUNTIF(Puzzles!E2:E97,"culture") -> 4
A12: games | B12: =COUNTIF(Puzzles!E2:E97,"games") -> 1
A13: geography | B13: =COUNTIF(Puzzles!E2:E97,"geography") -> 14
A14: geology | B14: =COUNTIF(Puzzles!E2:E97,"geology") -> 2
A15: history | B15: =COUNTIF(Puzzles!E2:E97,"history") -> 14
A16: language | B16: =COUNTIF(Puzzles!E2:E97,"language") -> 1
A17: literature | B17: =COUNTIF(Puzzles!E2:E97,"literature") -> 1
A18: mathematics | B18: =COUNTIF(Puzzles!E2:E97,"mathematics") -> 2
A19: measurement | B19: =COUNTIF(Puzzles!E2:E97,"measurement") -> 7
A20: music | B20: =COUNTIF(Puzzles!E2:E97,"music") -> 5
A21: nature | B21: =COUNTIF(Puzzles!E2:E97,"nature") -> 8
A22: science | B22: =COUNTIF(Puzzles!E2:E97,"science") -> 19
A23: sport | B23: =COUNTIF(Puzzles!E2:E97,"sport") -> 4
A24: technology | B24: =COUNTIF(Puzzles!E2:E97,"technology") -> 4
A25: transport | B25: =COUNTIF(Puzzles!E2:E97,"transport") -> 1
A26: Total | B26: =SUM(B9:B25) -> 95
